Workbook

Sheet Instructions
A1: Jima — Comprehensive QA Workbook
A2: Version 1.0 | August 30, 2026 | Idata Technologies | All cases are Planned / Not Yet Executed
A4: Topic | B4: Instruction
A5: Purpose | B5: Executable record for formal QA handoff. The HTML/PDF is the governing strategy; this workbook records execution.
A6: Status rule | B6: Do not mark Passed without evidence. Initial status is Planned / Not Yet Executed. Actual Result, Tester, Execution Date and Environment must be completed on execution.
A7: Execution | B7: Filter by cycle, module, priority, actor and status. Verify preconditions, use synthetic data, execute numbered steps, compare expected, capture evidence, reset safely.
A8: Evidence | B8: Store links or controlled repository references. Redact JWTs, passwords, secret values, database URLs, real PII, stack traces and signed backup URLs.
A9: Defects | B9: Log every mismatch in Defect Log and place its ID in Test Cases. Retest the fix and perform risk-based regression.
A10: Release | B10: Production deployment is blocked until mandatory cases pass and no unresolved Critical or High defect remains.
A11: Formulas | B11: Coverage Summary and Daily Execution Summary contain formulas. Spreadsheet software recalculates them on open; do not replace formulas with typed totals.
A12: Data safety | B12: Use Test Data Plan only. Never run destructive security checks or seed/synchronize a production database.

Sheet Coverage Summary
A1: Coverage Summary
A2: Formula-based counts; open in Excel/LibreOffice to calculate current execution metrics.
A4: Module | B4: Total | C4: Critical | D4: High | E4: Medium | F4: Passed | G4: Failed | H4: Blocked | I4: Not Executed | J4: Pass %
A5: Environment & Build | B5: =COUNTIF('Test Cases'!$B:$B,A5) | C5: =COUNTIFS('Test Cases'!$B:$B,A5,'Test Cases'!$G:$G,"Critical") | D5: =COUNTIFS('Test Cases'!$B:$B,A5,'Test Cases'!$G:$G,"High") | E5: =COUNTIFS('Test Cases'!$B:$B,A5,'Test Cases'!$G:$G,"Medium") | F5: =COUNTIFS('Test Cases'!$B:$B,A5,'Test Cases'!$R:$R,"Passed") | G5: =COUNTIFS('Test Cases'!$B:$B,A5,'Test Cases'!$R:$R,"Failed") | H5: =COUNTIFS('Test Cases'!$B:$B,A5,'Test Cases'!$R:$R,"Blocked") | I5: =COUNTIFS('Test Cases'!$B:$B,A5,'Test Cases'!$R:$R,"Planned / Not Yet Executed")+COUNTIFS('Test Cases'!$B:$B,A5,'Test Cases'!$R:$R,"Not Run") | J5: =IFERROR(F5/B5,0)
A6: Authentication & Session | B6: =COUNTIF('Test Cases'!$B:$B,A6) | C6: =COUNTIFS('Test Cases'!$B:$B,A6,'Test Cases'!$G:$G,"Critical") | D6: =COUNTIFS('Test Cases'!$B:$B,A6,'Test Cases'!$G:$G,"High") | E6: =COUNTIFS('Test Cases'!$B:$B,A6,'Test Cases'!$G:$G,"Medium") | F6: =COUNTIFS('Test Cases'!$B:$B,A6,'Test Cases'!$R:$R,"Passed") | G6: =COUNTIFS('Test Cases'!$B:$B,A6,'Test Cases'!$R:$R,"Failed") | H6: =COUNTIFS('Test Cases'!$B:$B,A6,'Test Cases'!$R:$R,"Blocked") | I6: =COUNTIFS('Test Cases'!$B:$B,A6,'Test Cases'!$R:$R,"Planned / Not Yet Executed")+COUNTIFS('Test Cases'!$B:$B,A6,'Test Cases'!$R:$R,"Not Run") | J6: =IFERROR(F6/B6,0)
A7: Role & Access Control | B7: =COUNTIF('Test Cases'!$B:$B,A7) | C7: =COUNTIFS('Test Cases'!$B:$B,A7,'Test Cases'!$G:$G,"Critical") | D7: =COUNTIFS('Test Cases'!$B:$B,A7,'Test Cases'!$G:$G,"High") | E7: =COUNTIFS('Test Cases'!$B:$B,A7,'Test Cases'!$G:$G,"Medium") | F7: =COUNTIFS('Test Cases'!$B:$B,A7,'Test Cases'!$R:$R,"Passed") | G7: =COUNTIFS('Test Cases'!$B:$B,A7,'Test Cases'!$R:$R,"Failed") | H7: =COUNTIFS('Test Cases'!$B:$B,A7,'Test Cases'!$R:$R,"Blocked") | I7: =COUNTIFS('Test Cases'!$B:$B,A7,'Test Cases'!$R:$R,"Planned / Not Yet Executed")+COUNTIFS('Test Cases'!$B:$B,A7,'Test Cases'!$R:$R,"Not Run") | J7: =IFERROR(F7/B7,0)
A8: Restaurant & Branch Isolation | B8: =COUNTIF('Test Cases'!$B:$B,A8) | C8: =COUNTIFS('Test Cases'!$B:$B,A8,'Test Cases'!$G:$G,"Critical") | D8: =COUNTIFS('Test Cases'!$B:$B,A8,'Test Cases'!$G:$G,"High") | E8: =COUNTIFS('Test Cases'!$B:$B,A8,'Test Cases'!$G:$G,"Medium") | F8: =COUNTIFS('Test Cases'!$B:$B,A8,'Test Cases'!$R:$R,"Passed") | G8: =COUNTIFS('Test Cases'!$B:$B,A8,'Test Cases'!$R:$R,"Failed") | H8: =COUNTIFS('Test Cases'!$B:$B,A8,'Test Cases'!$R:$R,"Blocked") | I8: =COUNTIFS('Test Cases'!$B:$B,A8,'Test Cases'!$R:$R,"Planned / Not Yet Executed")+COUNTIFS('Test Cases'!$B:$B,A8,'Test Cases'!$R:$R,"Not Run") | J8: =IFERROR(F8/B8,0)
A9: Dashboard | B9: =COUNTIF('Test Cases'!$B:$B,A9) | C9: =COUNTIFS('Test Cases'!$B:$B,A9,'Test Cases'!$G:$G,"Critical") | D9: =COUNTIFS('Test Cases'!$B:$B,A9,'Test Cases'!$G:$G,"High") | E9: =COUNTIFS('Test Cases'!$B:$B,A9,'Test Cases'!$G:$G,"Medium") | F9: =COUNTIFS('Test Cases'!$B:$B,A9,'Test Cases'!$R:$R,"Passed") | G9: =COUNTIFS('Test Cases'!$B:$B,A9,'Test Cases'!$R:$R,"Failed") | H9: =COUNTIFS('Test Cases'!$B:$B,A9,'Test Cases'!$R:$R,"Blocked") | I9: =COUNTIFS('Test Cases'!$B:$B,A9,'Test Cases'!$R:$R,"Planned / Not Yet Executed")+COUNTIFS('Test Cases'!$B:$B,A9,'Test Cases'!$R:$R,"Not Run") | J9: =IFERROR(F9/B9,0)
A10: Orders & POS | B10: =COUNTIF('Test Cases'!$B:$B,A10) | C10: =COUNTIFS('Test Cases'!$B:$B,A10,'Test Cases'!$G:$G,"Critical") | D10: =COUNTIFS('Test Cases'!$B:$B,A10,'Test Cases'!$G:$G,"High") | E10: =COUNTIFS('Test Cases'!$B:$B,A10,'Test Cases'!$G:$G,"Medium") | F10: =COUNTIFS('Test Cases'!$B:$B,A10,'Test Cases'!$R:$R,"Passed") | G10: =COUNTIFS('Test Cases'!$B:$B,A10,'Test Cases'!$R:$R,"Failed") | H10: =COUNTIFS('Test Cases'!$B:$B,A10,'Test Cases'!$R:$R,"Blocked") | I10: =COUNTIFS('Test Cases'!$B:$B,A10,'Test Cases'!$R:$R,"Planned / Not Yet Executed")+COUNTIFS('Test Cases'!$B:$B,A10,'Test Cases'!$R:$R,"Not Run") | J10: =IFERROR(F10/B10,0)
A11: Coordinator & Kitchen | B11: =COUNTIF('Test Cases'!$B:$B,A11) | C11: =COUNTIFS('Test Cases'!$B:$B,A11,'Test Cases'!$G:$G,"Critical") | D11: =COUNTIFS('Test Cases'!$B:$B,A11,'Test Cases'!$G:$G,"High") | E11: =COUNTIFS('Test Cases'!$B:$B,A11,'Test Cases'!$G:$G,"Medium") | F11: =COUNTIFS('Test Cases'!$B:$B,A11,'Test Cases'!$R:$R,"Passed") | G11: =COUNTIFS('Test Cases'!$B:$B,A11,'Test Cases'!$R:$R,"Failed") | H11: =COUNTIFS('Test Cases'!$B:$B,A11,'Test Cases'!$R:$R,"Blocked") | I11: =COUNTIFS('Test Cases'!$B:$B,A11,'Test Cases'!$R:$R,"Planned / Not Yet Executed")+COUNTIFS('Test Cases'!$B:$B,A11,'Test Cases'!$R:$R,"Not Run") | J11: =IFERROR(F11/B11,0)
A12: Payments & Shifts | B12: =COUNTIF('Test Cases'!$B:$B,A12) | C12: =COUNTIFS('Test Cases'!$B:$B,A12,'Test Cases'!$G:$G,"Critical") | D12: =COUNTIFS('Test Cases'!$B:$B,A12,'Test Cases'!$G:$G,"High") | E12: =COUNTIFS('Test Cases'!$B:$B,A12,'Test Cases'!$G:$G,"Medium") | F12: =COUNTIFS('Test Cases'!$B:$B,A12,'Test Cases'!$R:$R,"Passed") | G12: =COUNTIFS('Test Cases'!$B:$B,A12,'Test Cases'!$R:$R,"Failed") | H12: =COUNTIFS('Test Cases'!$B:$B,A12,'Test Cases'!$R:$R,"Blocked") | I12: =COUNTIFS('Test Cases'!$B:$B,A12,'Test Cases'!$R:$R,"Planned / Not Yet Executed")+COUNTIFS('Test Cases'!$B:$B,A12,'Test Cases'!$R:$R,"Not Run") | J12: =IFERROR(F12/B12,0)
A13: Menu & Categories | B13: =COUNTIF('Test Cases'!$B:$B,A13) | C13: =COUNTIFS('Test Cases'!$B:$B,A13,'Test Cases'!$G:$G,"Critical") | D13: =COUNTIFS('Test Cases'!$B:$B,A13,'Test Cases'!$G:$G,"High") | E13: =COUNTIFS('Test Cases'!$B:$B,A13,'Test Cases'!$G:$G,"Medium") | F13: =COUNTIFS('Test Cases'!$B:$B,A13,'Test Cases'!$R:$R,"Passed") | G13: =COUNTIFS('Test Cases'!$B:$B,A13,'Test Cases'!$R:$R,"Failed") | H13: =COUNTIFS('Test Cases'!$B:$B,A13,'Test Cases'!$R:$R,"Blocked") | I13: =COUNTIFS('Test Cases'!$B:$B,A13,'Test Cases'!$R:$R,"Planned / Not Yet Executed")+COUNTIFS('Test Cases'!$B:$B,A13,'Test Cases'!$R:$R,"Not Run") | J13: =IFERROR(F13/B13,0)
A14: Tables | B14: =COUNTIF('Test Cases'!$B:$B,A14) | C14: =COUNTIFS('Test Cases'!$B:$B,A14,'Test Cases'!$G:$G,"Critical") | D14: =COUNTIFS('Test Cases'!$B:$B,A14,'Test Cases'!$G:$G,"High") | E14: =COUNTIFS('Test Cases'!$B:$B,A14,'Test Cases'!$G:$G,"Medium") | F14: =COUNTIFS('Test Cases'!$B:$B,A14,'Test Cases'!$R:$R,"Passed") | G14: =COUNTIFS('Test Cases'!$B:$B,A14,'Test Cases'!$R:$R,"Failed") | H14: =COUNTIFS('Test Cases'!$B:$B,A14,'Test Cases'!$R:$R,"Blocked") | I14: =COUNTIFS('Test Cases'!$B:$B,A14,'Test Cases'!$R:$R,"Planned / Not Yet Executed")+COUNTIFS('Test Cases'!$B:$B,A14,'Test Cases'!$R:$R,"Not Run") | J14: =IFERROR(F14/B14,0)
A15: Staff & Branches | B15: =COUNTIF('Test Cases'!$B:$B,A15) | C15: =COUNTIFS('Test Cases'!$B:$B,A15,'Test Cases'!$G:$G,"Critical") | D15: =COUNTIFS('Test Cases'!$B:$B,A15,'Test Cases'!$G:$G,"High") | E15: =COUNTIFS('Test Cases'!$B:$B,A15,'Test Cases'!$G:$G,"Medium") | F15: =COUNTIFS('Test Cases'!$B:$B,A15,'Test Cases'!$R:$R,"Passed") | G15: =COUNTIFS('Test Cases'!$B:$B,A15,'Test Cases'!$R:$R,"Failed") | H15: =COUNTIFS('Test Cases'!$B:$B,A15,'Test Cases'!$R:$R,"Blocked") | I15: =COUNTIFS('Test Cases'!$B:$B,A15,'Test Cases'!$R:$R,"Planned / Not Yet Executed")+COUNTIFS('Test Cases'!$B:$B,A15,'Test Cases'!$R:$R,"Not Run") | J15: =IFERROR(F15/B15,0)
A16: Branch Inventory & Procurement | B16: =COUNTIF('Test Cases'!$B:$B,A16) | C16: =COUNTIFS('Test Cases'!$B:$B,A16,'Test Cases'!$G:$G,"Critical") | D16: =COUNTIFS('Test Cases'!$B:$B,A16,'Test Cases'!$G:$G,"High") | E16: =COUNTIFS('Test Cases'!$B:$B,A16,'Test Cases'!$G:$G,"Medium") | F16: =COUNTIFS('Test Cases'!$B:$B,A16,'Test Cases'!$R:$R,"Passed") | G16: =COUNTIFS('Test Cases'!$B:$B,A16,'Test Cases'!$R:$R,"Failed") | H16: =COUNTIFS('Test Cases'!$B:$B,A16,'Test Cases'!$R:$R,"Blocked") | I16: =COUNTIFS('Test Cases'!$B:$B,A16,'Test Cases'!$R:$R,"Planned / Not Yet Executed")+COUNTIFS('Test Cases'!$B:$B,A16,'Test Cases'!$R:$R,"Not Run") | J16: =IFERROR(F16/B16,0)
... A31: UAT & Release Sign-off | B31: =COUNTIF('Test Cases'!$B:$B,A31) | C31: =COUNTIFS('Test Cases'!$B:$B,A31,'Test Cases'!$G:$G,"Critical") | D31: =COUNTIFS('Test Cases'!$B:$B,A31,'Test Cases'!$G:$G,"High") | E31: =COUNTIFS('Test Cases'!$B:$B,A31,'Test Cases'!$G:$G,"Medium") | F31: =COUNTIFS('Test Cases'!$B:$B,A31,'Test Cases'!$R:$R,"Passed") | G31: =COUNTIFS('Test Cases'!$B:$B,A31,'Test Cases'!$R:$R,"Failed") | H31: =COUNTIFS('Test Cases'!$B:$B,A31,'Test Cases'!$R:$R,"Blocked") | I31: =COUNTIFS('Test Cases'!$B:$B,A31,'Test Cases'!$R:$R,"Planned / Not Yet Executed")+COUNTIFS('Test Cases'!$B:$B,A31,'Test Cases'!$R:$R,"Not Run") | J31: =IFERROR(F31/B31,0)
A34: Release-gate indicator | B34: Formula/result | C34: Required state
A35: Unresolved Critical/High defects | B35: =COUNTIFS('Defect Log'!$C:$C,"Critical",'Defect Log'!$E:$E,"<>Closed")+COUNTIFS('Defect Log'!$C:$C,"High",'Defect Log'!$E:$E,"<>Closed") | C35: 0
A36: Mandatory Critical/High not passed | B36: =COUNTIFS('Test Cases'!$G:$G,"Critical",'Test Cases'!$R:$R,"<>Passed")+COUNTIFS('Test Cases'!$G:$G,"High",'Test Cases'!$R:$R,"<>Passed") | C36: 0
A37: Release checklist incomplete | B37: =COUNTIF('Release Gate Checklist'!$D:$D,"<>Passed")-1 | C37: 0
A38: Overall decision | B38: =IF(AND(B35=0,B36=0,B37=0),"ELIGIBLE FOR APPROVAL","BLOCKED") | C38: ELIGIBLE FOR APPROVAL

Sheet Test Cases
A1: Test ID | B1: Module | C1: Requirement ID(s) | D1: Title | E1: Objective | F1: Type | G1: Priority | H1: Risk | I1: Preconditions | J1: Test Data | K1: Actor/Role | L1: Branch/Restaurant Context | M1: Numbered Steps | N1: Expected Result | O1: Cleanup/Reset | P1: Automation Candidate | Q1: Evidence Required | R1: Status | S1: Actual Result | T1: Defect ID | U1: Tester | V1: Execution Date | W1: Environment | X1: Notes
A2: ENV-001 | B2: Environment & Build | C2: NFR-06, NFR-07 | D2: Clean install resolves the locked dependency graph | E2: Verify, without assuming a pass result, that the release candidate correctly enforces: Clean install resolves the locked dependency graph. | F2: Positive | G2: Medium | H2: Medium | I2: Clean release candidate; documented Node 18+, pnpm and PostgreSQL 14+; isolated QA environment. | J2: Use only named synthetic records from the Test Data Plan; capture generated IDs and baseline values in evidence. Never use real credentials, customer PII or secrets. | K2: QA Lead / Release Engineer | L2: Isolated QA or staging; never production unless the approved smoke step explicitly says so | M2: 1. Sign in as QA Lead / Release Engineer, or remain anonymous when the case requires it. 2. Record relevant UI, API and database baseline identifiers, statuses, counts and balances. 3. Use the documented page/API to verify that clean install resolves the locked dependency graph. 4. Refresh or repeat through an independent client where concurrency, polling or idempotency applies. 5. Compare the outcome, scope, audit fields and side effects with the expected result; capture evidence. | N2: The release candidate demonstrates the specified behavior exactly and only within the actor's authorized scope: Clean install resolves the locked dependency graph. No unrelated record changes. | O2: Reverse only synthetic changes through supported UI/API, or restore the approved isolated snapshot; confirm no residual locks, sessions, occupied tables or stock deltas. | P2: Yes | Q2: Timestamped screenshots for UI; request/response with secrets redacted for API; query IDs/counts/balances for transactions; export/build artifact or monitoring trace where applicable. | R2: Planned / Not Yet Executed
A3: ENV-002 | B3: Environment & Build | C3: NFR-06, NFR-07 | D3: Frontend TypeScript static check completes without errors | E3: Verify, without assuming a pass result, that the release candidate correctly enforces: Frontend TypeScript static check completes without errors. | F3: Negative | G3: Medium | H3: Medium | I3: Clean release candidate; documented Node 18+, pnpm and PostgreSQL 14+; isolated QA environment. | J3: Use only named synthetic records from the Test Data Plan; capture generated IDs and baseline values in evidence. Never use real credentials, customer PII or secrets. | K3: QA Lead / Release Engineer | L3: Isolated QA or staging; never production unless the approved smoke step explicitly says so | M3: 1. Sign in as QA Lead / Release Engineer, or remain anonymous when the case requires it. 2. Record relevant UI, API and database baseline identifiers, statuses, counts and balances. 3. Use the documented page/API to verify that frontend TypeScript static check completes without errors. 4. Refresh or repeat through an independent client where concurrency, polling or idempotency applies. 5. Compare the outcome, scope, audit fields and side effects with the expected result; capture evidence. | N3: The release candidate demonstrates the specified behavior exactly and only within the actor's authorized scope: Frontend TypeScript static check completes without errors. No unrelated record changes. | O3: Reverse only synthetic changes through supported UI/API, or restore the approved isolated snapshot; confirm no residual locks, sessions, occupied tables or stock deltas. | P3: Yes | Q3: Timestamped screenshots for UI; request/response with secrets redacted for API; query IDs/counts/balances for transactions; export/build artifact or monitoring trace where applicable. | R3: Planned / Not Yet Executed
A4: ENV-003 | B4: Environment & Build | C4: NFR-06, NFR-07 | D4: Backend TypeScript static check completes without errors | E4: Verify, without assuming a pass result, that the release candidate correctly enforces: Backend TypeScript static check completes without errors. | F4: Negative | G4: Medium | H4: Medium | I4: Clean release candidate; documented Node 18+, pnpm and PostgreSQL 14+; isolated QA environment. | J4: Use only named synthetic records from the Test Data Plan; capture generated IDs and baseline values in evidence. Never use real credentials, customer PII or secrets. | K4: QA Lead / Release Engineer | L4: Isolated QA or staging; never production unless the approved smoke step explicitly says so | M4: 1. Sign in as QA Lead / Release Engineer, or remain anonymous when the case requires it. 2. Record relevant UI, API and database baseline identifiers, statuses, counts and balances. 3. Use the documented page/API to verify that backend TypeScript static check completes without errors. 4. Refresh or repeat through an independent client where concurrency, polling or idempotency applies. 5. Compare the outcome, scope, audit fields and side effects with the expected result; capture evidence. | N4: The release candidate demonstrates the specified behavior exactly and only within the actor's authorized scope: Backend TypeScript static check completes without errors. No unrelated record changes. | O4: Reverse only synthetic changes through supported UI/API, or restore the approved isolated snapshot; confirm no residual locks, sessions, occupied tables or stock deltas. | P4: Yes | Q4: Timestamped screenshots for UI; request/response with secrets redacted for API; query IDs/counts/balances for transactions; export/build artifact or monitoring trace where applicable. | R4: Planned / Not Yet Executed
A5: ENV-004 | B5: Environment & Build | C5: NFR-06, NFR-07 | D5: Production frontend build uses the registered Jima source | E5: Verify, without assuming a pass result, that the release candidate correctly enforces: Production frontend build uses the registered Jima source. | F5: Positive | G5: Medium | H5: Medium | I5: Clean release candidate; documented Node 18+, pnpm and PostgreSQL 14+; isolated QA environment. | J5: Use only named synthetic records from the Test Data Plan; capture generated IDs and baseline values in evidence. Never use real credentials, customer PII or secrets. | K5: QA Lead / Release Engineer | L5: Isolated QA or staging; never production unless the approved smoke step explicitly says so | M5: 1. Sign in as QA Lead / Release Engineer, or remain anonymous when the case requires it. 2. Record relevant UI, API and database baseline identifiers, statuses, counts and balances. 3. Use the documented page/API to verify that production frontend build uses the registered Jima source. 4. Refresh or repeat through an independent client where concurrency, polling or idempotency applies. 5. Compare the outcome, scope, audit fields and side effects with the expected result; capture evidence. | N5: The release candidate demonstrates the specified behavior exactly and only within the actor's authorized scope: Production frontend build uses the registered Jima source. No unrelated record changes. | O5: Reverse only synthetic changes through supported UI/API, or restore the approved isolated snapshot; confirm no residual locks, sessions, occupied tables or stock deltas. | P5: Yes | Q5: Timestamped screenshots for UI; request/response with secrets redacted for API; query IDs/counts/balances for transactions; export/build artifact or monitoring trace where applicable. | R5: Planned / Not Yet Executed
A6: ENV-005 | B6: Environment & Build | C6: NFR-06, NFR-07 | D6: Backend package build produces a startable artifact | E6: Verify, without assuming a pass result, that the release candidate correctly enforces: Backend package build produces a startable artifact. | F6: Positive | G6: Medium | H6: Medium | I6: Clean release candidate; documented Node 18+, pnpm and PostgreSQL 14+; isolated QA environment. | J6: Use only named synthetic records from the Test Data Plan; capture generated IDs and baseline values in evidence. Never use real credentials, customer PII or secrets. | K6: QA Lead / Release Engineer | L6: Isolated QA or staging; never production unless the approved smoke step explicitly says so | M6: 1. Sign in as QA Lead / Release Engineer, or remain anonymous when the case requires it. 2. Record relevant UI, API and database baseline identifiers, statuses, counts and balances. 3. Use the documented page/API to verify that backend package build produces a startable artifact. 4. Refresh or repeat through an independent client where concurrency, polling or idempotency applies. 5. Compare the outcome, scope, audit fields and side effects with the expected result; capture evidence. | N6: The release candidate demonstrates the specified behavior exactly and only within the actor's authorized scope: Backend package build produces a startable artifact. No unrelated record changes. | O6: Reverse only synthetic changes through supported UI/API, or restore the approved isolated snapshot; confirm no residual locks, sessions, occupied tables or stock deltas. | P6: Yes | Q6: Timestamped screenshots for UI; request/response with secrets redacted for API; query IDs/counts/balances for transactions; export/build artifact or monitoring trace where applicable. | R6: Planned / Not Yet Executed
A7: ENV-006 | B7: Environment & Build | C7: NFR-06, NFR-07 | D7: Required environment variables are detected without exposing values | E7: Verify, without assuming a pass result, that the release candidate correctly enforces: Required environment variables are detected without exposing values. | F7: Negative | G7: Medium | H7: Medium | I7: Clean release candidate; documented Node 18+, pnpm and PostgreSQL 14+; isolated QA environment. | J7: Use only named synthetic records from the Test Data Plan; capture generated IDs and baseline values in evidence. Never use real credentials, customer PII or secrets. | K7: QA Lead / Release Engineer | L7: Isolated QA or staging; never production unless the approved smoke step explicitly says so | M7: 1. Sign in as QA Lead / Release Engineer, or remain anonymous when the case requires it. 2. Record relevant UI, API and database baseline identifiers, statuses, counts and balances. 3. Use the documented page/API to verify that required environment variables are detected without exposing values. 4. Refresh or repeat through an independent client where concurrency, polling or idempotency applies. 5. Compare the outcome, scope, audit fields and side effects with the expected result; capture evidence. | N7: The release candidate demonstrates the specified behavior exactly and only within the actor's authorized scope: Required environment variables are detected without exposing values. No unrelated record changes. | O7: Reverse only synthetic changes through supported UI/API, or restore the approved isolated snapshot; confirm no residual locks, sessions, occupied tables or stock deltas. | P7: Yes | Q7: Timestamped screenshots for UI; request/response with secrets redacted for API; query IDs/counts/balances for transactions; export/build artifact or monitoring trace where applicable. | R7: Planned / Not Yet Executed
A8: ENV-007 | B8: Environment & Build | C8: NFR-06, NFR-07 | D8: Health endpoint confirms service and database readiness | E8: Verify, without assuming a pass result, that the release candidate correctly enforces: Health endpoint confirms service and database readiness. | F8: Positive | G8: Medium | H8: Medium | I8: Clean release candidate; documented Node 18+, pnpm and PostgreSQL 14+; isolated QA environment. | J8: Use only named synthetic records from the Test Data Plan; capture generated IDs and baseline values in evidence. Never use real credentials, customer PII or secrets. | K8: QA Lead / Release Engineer | L8: Isolated QA or staging; never production unless the approved smoke step explicitly says so | M8: 1. Sign in as QA Lead / Release Engineer, or remain anonymous when the case requires it. 2. Record relevant UI, API and database baseline identifiers, statuses, counts and balances. 3. Use the documented page/API to verify that health endpoint confirms service and database readiness. 4. Refresh or repeat through an independent client where concurrency, polling or idempotency applies. 5. Compare the outcome, scope, audit fields and side effects with the expected result; capture evidence. | N8: The release candidate demonstrates the specified behavior exactly and only within the actor's authorized scope: Health endpoint confirms service and database readiness. No unrelated record changes. | O8: Reverse only synthetic changes through supported UI/API, or restore the approved isolated snapshot; confirm no residual locks, sessions, occupied tables or stock deltas. | P8: Yes | Q8: Timestamped screenshots for UI; request/response with secrets redacted for API; query IDs/counts/balances for transactions; export/build artifact or monitoring trace where applicable. | R8: Planned / Not Yet Executed
A9: ENV-008 | B9: Environment & Build | C9: NFR-06, NFR-07 | D9: Missing build or test script is reported as a gap, not a pass | E9: Verify, without assuming a pass result, that the release candidate correctly enforces: Missing build or test script is reported as a gap, not a pass. | F9: Negative | G9: Medium | H9: Medium | I9: Clean release candidate; documented Node 18+, pnpm and PostgreSQL 14+; isolated QA environment. | J9: Use only named synthetic records from the Test Data Plan; capture generated IDs and baseline values in evidence. Never use real credentials, customer PII or secrets. | K9: QA Lead / Release Engineer | L9: Isolated QA or staging; never production unless the approved smoke step explicitly says so | M9: 1. Sign in as QA Lead / Release Engineer, or remain anonymous when the case requires it. 2. Record relevant UI, API and database baseline identifiers, statuses, counts and balances. 3. Use the documented page/API to verify that missing build or test script is reported as a gap, not a pass. 4. Refresh or repeat through an independent client where concurrency, polling or idempotency applies. 5. Compare the outcome, scope, audit fields and side effects with the expected result; capture evidence. | N9: The release candidate demonstrates the specified behavior exactly and only within the actor's authorized scope: Missing build or test script is reported as a gap, not a pass. No unrelated record changes. | O9: Reverse only synthetic changes through supported UI/API, or restore the approved isolated snapshot; confirm no residual locks, sessions, occupied tables or stock deltas. | P9: Yes | Q9: Timestamped screenshots for UI; request/response with secrets redacted for API; query IDs/counts/balances for transactions; export/build artifact or monitoring trace where applicable. | R9: Planned / Not Yet Executed
A10: AUTH-001 | B10: Authentication & Session | C10: FR-A01, FR-A02, FR-A04, NFR-03 | D10: Valid active user signs in and receives a JWT | E10: Verify, without assuming a pass result, that the release candidate correctly enforces: Valid active user signs in and receives a JWT. | F10: Positive | G10: Medium | H10: Medium | I10: Synthetic active and inactive users exist; login endpoint and protected page are available. | J10: Use only named synthetic records from the Test Data Plan; capture generated IDs and baseline values in evidence. Never use real credentials, customer PII or secrets. | K10: Any role / Anonymous | L10: Restaurant A / Branch A1 unless the case explicitly tests another scope | M10: 1. Sign in as Any role / Anonymous, or remain anonymous when the case requires it. 2. Record relevant UI, API and database baseline identifiers, statuses, counts and balances. 3. Use the documented page/API to verify that valid active user signs in and receives a JWT. 4. Refresh or repeat through an independent client where concurrency, polling or idempotency applies. 5. Compare the outcome, scope, audit fields and side effects with the expected result; capture evidence. | N10: The release candidate demonstrates the specified behavior exactly and only within the actor's authorized scope: Valid active user signs in and receives a JWT. No unrelated record changes. | O10: Reverse only synthetic changes through supported UI/API, or restore the approved isolated snapshot; confirm no residual locks, sessions, occupied tables or stock deltas. | P10: Yes | Q10: Timestamped screenshots for UI; request/response with secrets redacted for API; query IDs/counts/balances for transactions; export/build artifact or monitoring trace where applicable. | R10: Planned / Not Yet Executed
A11: AUTH-002 | B11: Authentication & Session | C11: FR-A01, FR-A02, FR-A04, NFR-03 | D11: Invalid password is rejected without account disclosure | E11: Verify, without assuming a pass result, that the release candidate correctly enforces: Invalid password is rejected without account disclosure. | F11: Negative | G11: Critical | H11: Critical | I11: Synthetic active and inactive users exist; login endpoint and protected page are available. | J11: Use only named synthetic records from the Test Data Plan; capture generated IDs and baseline values in evidence. Never use real credentials, customer PII or secrets. | K11: Any role / Anonymous | L11: Restaurant A / Branch A1 unless the case explicitly tests another scope | M11: 1. Sign in as Any role / Anonymous, or remain anonymous when the case requires it. 2. Record relevant UI, API and database baseline identifiers, statuses, counts and balances. 3. Use the documented page/API to verify that invalid password is rejected without account disclosure. 4. Refresh or repeat through an independent client where concurrency, polling or idempotency applies. 5. Compare the outcome, scope, audit fields and side effects with the expected result; capture evidence. | N11: The operation is refused with a stable, safe error; no unauthorized or partial mutation occurs. Specifically: Invalid password is rejected without account disclosure. | O11: Reverse only synthetic changes through supported UI/API, or restore the approved isolated snapshot; confirm no residual locks, sessions, occupied tables or stock deltas. | P11: Yes | Q11: Timestamped screenshots for UI; request/response with secrets redacted for API; query IDs/counts/balances for transactions; export/build artifact or monitoring trace where applicable. | R11: Planned / Not Yet Executed
A12: AUTH-003 | B12: Authentication & Session | C12: FR-A01, FR-A02, FR-A04, NFR-03 | D12: Unknown email is rejected with a stable generic error | E12: Verify, without assuming a pass result, that the release candidate correctly enforces: Unknown email is rejected with a stable generic error. | F12: Negative | G12: Medium | H12: Medium | I12: Synthetic active and inactive users exist; login endpoint and protected page are available. | J12: Use only named synthetic records from the Test Data Plan; capture generated IDs and baseline values in evidence. Never use real credentials, customer PII or secrets. | K12: Any role / Anonymous | L12: Restaurant A / Branch A1 unless the case explicitly tests another scope | M12: 1. Sign in as Any role / Anonymous, or remain anonymous when the case requires it. 2. Record relevant UI, API and database baseline identifiers, statuses, counts and balances. 3. Use the documented page/API to verify that unknown email is rejected with a stable generic error. 4. Refresh or repeat through an independent client where concurrency, polling or idempotency applies. 5. Compare the outcome, scope, audit fields and side effects with the expected result; capture evidence. | N12: The operation is refused with a stable, safe error; no unauthorized or partial mutation occurs. Specifically: Unknown email is rejected with a stable generic error. | O12: Reverse only synthetic changes through supported UI/API, or restore the approved isolated snapshot; confirm no residual locks, sessions, occupied tables or stock deltas. | P12: Yes | Q12: Timestamped screenshots for UI; request/response with secrets redacted for API; query IDs/counts/balances for transactions; export/build artifact or monitoring trace where applicable. | R12: Planned / Not Yet Executed
A13: AUTH-004 | B13: Authentication & Session | C13: FR-A01, FR-A02, FR-A04, NFR-03 | D13: Inactive account cannot authenticate | E13: Verify, without assuming a pass result, that the release candidate correctly enforces: Inactive account cannot authenticate. | F13: Negative | G13: Medium | H13: Medium | I13: Synthetic active and inactive users exist; login endpoint and protected page are available. | J13: Use only named synthetic records from the Test Data Plan; capture generated IDs and baseline values in evidence. Never use real credentials, customer PII or secrets. | K13: Any role / Anonymous | L13: Restaurant A / Branch A1 unless the case explicitly tests another scope | M13: 1. Sign in as Any role / Anonymous, or remain anonymous when the case requires it. 2. Record relevant UI, API and database baseline identifiers, statuses, counts and balances. 3. Use the documented page/API to verify that inactive account cannot authenticate. 4. Refresh or repeat through an independent client where concurrency, polling or idempotency applies. 5. Compare the outcome, scope, audit fields and side effects with the expected result; capture evidence. | N13: The operation is refused with a stable, safe error; no unauthorized or partial mutation occurs. Specifically: Inactive account cannot authenticate. | O13: Reverse only synthetic changes through supported UI/API, or restore the approved isolated snapshot; confirm no residual locks, sessions, occupied tables or stock deltas. | P13: Yes | Q13: Timestamped screenshots for UI; request/response with secrets redacted for API; query IDs/counts/balances for transactions; export/build artifact or monitoring trace where applicable. | R13: Planned / Not Yet Executed
... A239: UAT-004 | B239: UAT & Release Sign-off | C239: FR-O02, FR-P02, FR-I09, NFR-04 | D239: Release approval is blocked until mandatory gates are signed | E239: Verify, without assuming a pass result, that the release candidate correctly enforces: Release approval is blocked until mandatory gates are signed. | F239: Integration | G239: Medium | H239: Medium | I239: Mandatory QA cycles are complete and UAT users have approved synthetic scenarios. | J239: Use only named synthetic records from the Test Data Plan; capture generated IDs and baseline values in evidence. Never use real credentials, customer PII or secrets. | K239: Business Owner / Department leads | L239: Restaurant A / Branch A1 unless the case explicitly tests another scope | M239: 1. Sign in as Business Owner / Department leads, or remain anonymous when the case requires it. 2. Record relevant UI, API and database baseline identifiers, statuses, counts and balances. 3. Use the documented page/API to verify that release approval is blocked until mandatory gates are signed. 4. Refresh or repeat through an independent client where concurrency, polling or idempotency applies. 5. Compare the outcome, scope, audit fields and side effects with the expected result; capture evidence. | N239: The release candidate demonstrates the specified behavior exactly and only within the actor's authorized scope: Release approval is blocked until mandatory gates are signed. No unrelated record changes. | O239: Reverse only synthetic changes through supported UI/API, or restore the approved isolated snapshot; confirm no residual locks, sessions, occupied tables or stock deltas. | P239: Partial | Q239: Timestamped screenshots for UI; request/response with secrets redacted for API; query IDs/counts/balances for transactions; export/build artifact or monitoring trace where applicable. | R239: Planned / Not Yet Executed

Sheet Role & Access Matrix
A1: Role & Access Matrix
A2: UI visibility is not authorization evidence. Verify each allowed, scoped and denied action against the backend.
A4: Role | B4: Landing / core access | C4: Dashboard | D4: Orders/POS | E4: Coordinator actions | F4: Kitchen | G4: Payments | H4: Menu/Tables | I4: Staff/Branches | J4: Branch Inventory / Item Requests | K4: Main Store request | L4: Decision | M4: Fulfillment
A5: Admin | B5: Dashboard | C5: Allowed | D5: Management visibility | E5: As configured | F5: Management visibility | G5: Management visibility | H5: Allowed | I5: Allowed | J5: Allowed | K5: Restaurant oversight | L5: As authorized | M5: Denied unless branchless storekeeper
A6: Owner | B6: Dashboard | C6: Allowed | D6: Restaurant visibility | E6: Management visibility | F6: Management visibility | G6: Reports only | H6: Allowed | I6: Restaurant management | J6: Restaurant visibility | K6: Restaurant visibility | L6: Allowed: same restaurant | M6: Denied
A7: Manager | B7: Dashboard | C7: Allowed | D7: Assigned branch | E7: Operational visibility | F7: Operational visibility | G7: Reports/oversight | H7: Allowed | I7: Assigned branch | J7: Assigned branch | K7: Assigned branch only | L7: Allowed: destination branch | M7: Denied
A8: Coordinator | B8: Orders | C8: Denied | D8: Assigned branch list | E8: Confirm/assign/cancel | F8: Progress visibility | G8: Denied | H8: Denied | I8: Denied | J8: Denied | K8: Denied | L8: Denied | M8: Denied
A9: Waiter | B9: Orders/POS | C9: Denied | D9: Create/append/serve in branch | E9: Denied | F9: Progress visibility | G9: Denied | H9: Denied | I9: Denied | J9: Denied | K9: Denied | L9: Denied | M9: Denied
A10: Chef | B10: Kitchen | C10: Denied | D10: Assigned queue context | E10: Denied | F10: Accept/prepare/ready | G10: Denied | H10: Denied | I10: Denied | J10: Denied | K10: Denied | L10: Denied | M10: Denied
A11: Cashier | B11: Orders/Payments | C11: Denied | D11: Served/paid context | E11: Denied | F11: Denied | G11: Allowed + reduced reports | H11: Denied | I11: Denied | J11: Denied | K11: Denied | L11: Denied | M11: Denied
A12: Branch Storekeeper | B12: Inventory/Requests | C12: Denied | D12: Denied | E12: Denied | F12: Denied | G12: Denied | H12: Denied | I12: Denied | J12: Assigned branch + legacy requests | K12: Create for assigned branch | L12: Denied | M12: Denied
A13: Main Store Storekeeper | B13: Main Store | C13: Denied | D13: Denied | E13: Denied | F13: Denied | G13: Denied | H13: Denied | I13: Denied | J13: Main Store receipts | K13: Restaurant approved queue | L13: Denied | M13: Allowed: approved/same restaurant

Sheet Requirements Traceability
A1: Requirements Traceability
A2: Formula counts link requirement IDs to the Test Cases sheet; multiple requirement IDs per case are counted by wildcard.
A4: Requirement ID | B4: Source / area | C4: Requirement summary | D4: Planned cases | E4: Passed cases | F4: Coverage status
A5: FR-A01 | B5: FRS/SRS | C5: Login with email/password and JWT | D5: =COUNTIF('Test Cases'!$C:$C,"*FR-A01*") | E5: =COUNTIFS('Test Cases'!$C:$C,"*FR-A01*",'Test Cases'!$R:$R,"Passed") | F5: =IF(D5=0,"GAP",IF(E5=D5,"VERIFIED","PLANNED / INCOMPLETE"))
A6: FR-A02 | B6: FRS/SRS | C6: Bearer protection | D6: =COUNTIF('Test Cases'!$C:$C,"*FR-A02*") | E6: =COUNTIFS('Test Cases'!$C:$C,"*FR-A02*",'Test Cases'!$R:$R,"Passed") | F6: =IF(D6=0,"GAP",IF(E6=D6,"VERIFIED","PLANNED / INCOMPLETE"))
A7: FR-A03 | B7: FRS/SRS | C7: Role-restricted UI/pages | D7: =COUNTIF('Test Cases'!$C:$C,"*FR-A03*") | E7: =COUNTIFS('Test Cases'!$C:$C,"*FR-A03*",'Test Cases'!$R:$R,"Passed") | F7: =IF(D7=0,"GAP",IF(E7=D7,"VERIFIED","PLANNED / INCOMPLETE"))
A8: FR-A04 | B8: FRS/SRS | C8: bcrypt passwords | D8: =COUNTIF('Test Cases'!$C:$C,"*FR-A04*") | E8: =COUNTIFS('Test Cases'!$C:$C,"*FR-A04*",'Test Cases'!$R:$R,"Passed") | F8: =IF(D8=0,"GAP",IF(E8=D8,"VERIFIED","PLANNED / INCOMPLETE"))
A9: FR-O01 | B9: FRS/SRS | C9: POS order creation | D9: =COUNTIF('Test Cases'!$C:$C,"*FR-O01*") | E9: =COUNTIFS('Test Cases'!$C:$C,"*FR-O01*",'Test Cases'!$R:$R,"Passed") | F9: =IF(D9=0,"GAP",IF(E9=D9,"VERIFIED","PLANNED / INCOMPLETE"))
A10: FR-O02 | B10: FRS/SRS | C10: Order lifecycle | D10: =COUNTIF('Test Cases'!$C:$C,"*FR-O02*") | E10: =COUNTIFS('Test Cases'!$C:$C,"*FR-O02*",'Test Cases'!$R:$R,"Passed") | F10: =IF(D10=0,"GAP",IF(E10=D10,"VERIFIED","PLANNED / INCOMPLETE"))
A11: FR-O03 | B11: FRS/SRS | C11: Coordinator confirm/assign | D11: =COUNTIF('Test Cases'!$C:$C,"*FR-O03*") | E11: =COUNTIFS('Test Cases'!$C:$C,"*FR-O03*",'Test Cases'!$R:$R,"Passed") | F11: =IF(D11=0,"GAP",IF(E11=D11,"VERIFIED","PLANNED / INCOMPLETE"))
A12: FR-O04 | B12: FRS/SRS | C12: Append items | D12: =COUNTIF('Test Cases'!$C:$C,"*FR-O04*") | E12: =COUNTIFS('Test Cases'!$C:$C,"*FR-O04*",'Test Cases'!$R:$R,"Passed") | F12: =IF(D12=0,"GAP",IF(E12=D12,"VERIFIED","PLANNED / INCOMPLETE"))
A13: FR-O05 | B13: FRS/SRS | C13: Order list/detail | D13: =COUNTIF('Test Cases'!$C:$C,"*FR-O05*") | E13: =COUNTIFS('Test Cases'!$C:$C,"*FR-O05*",'Test Cases'!$R:$R,"Passed") | F13: =IF(D13=0,"GAP",IF(E13=D13,"VERIFIED","PLANNED / INCOMPLETE"))
A14: FR-O06 | B14: FRS/SRS | C14: Order filters | D14: =COUNTIF('Test Cases'!$C:$C,"*FR-O06*") | E14: =COUNTIFS('Test Cases'!$C:$C,"*FR-O06*",'Test Cases'!$R:$R,"Passed") | F14: =IF(D14=0,"GAP",IF(E14=D14,"VERIFIED","PLANNED / INCOMPLETE"))
A15: FR-O07 | B15: FRS/SRS | C15: 10-second refresh | D15: =COUNTIF('Test Cases'!$C:$C,"*FR-O07*") | E15: =COUNTIFS('Test Cases'!$C:$C,"*FR-O07*",'Test Cases'!$R:$R,"Passed") | F15: =IF(D15=0,"GAP",IF(E15=D15,"VERIFIED","PLANNED / INCOMPLETE"))
A16: FR-O08 | B16: FRS/SRS | C16: Phone POS | D16: =COUNTIF('Test Cases'!$C:$C,"*FR-O08*") | E16: =COUNTIFS('Test Cases'!$C:$C,"*FR-O08*",'Test Cases'!$R:$R,"Passed") | F16: =IF(D16=0,"GAP",IF(E16=D16,"VERIFIED","PLANNED / INCOMPLETE"))
A17: FR-K01 | B17: FRS/SRS | C17: Chef queues | D17: =COUNTIF('Test Cases'!$C:$C,"*FR-K01*") | E17: =COUNTIFS('Test Cases'!$C:$C,"*FR-K01*",'Test Cases'!$R:$R,"Passed") | F17: =IF(D17=0,"GAP",IF(E17=D17,"VERIFIED","PLANNED / INCOMPLETE"))
A18: FR-K02 | B18: FRS/SRS | C18: Kitchen transitions | D18: =COUNTIF('Test Cases'!$C:$C,"*FR-K02*") | E18: =COUNTIFS('Test Cases'!$C:$C,"*FR-K02*",'Test Cases'!$R:$R,"Passed") | F18: =IF(D18=0,"GAP",IF(E18=D18,"VERIFIED","PLANNED / INCOMPLETE"))
A19: FR-K03 | B19: FRS/SRS | C19: Progress board | D19: =COUNTIF('Test Cases'!$C:$C,"*FR-K03*") | E19: =COUNTIFS('Test Cases'!$C:$C,"*FR-K03*",'Test Cases'!$R:$R,"Passed") | F19: =IF(D19=0,"GAP",IF(E19=D19,"VERIFIED","PLANNED / INCOMPLETE"))
A20: FR-K04 | B20: FRS/SRS | C20: 20-minute warning | D20: =COUNTIF('Test Cases'!$C:$C,"*FR-K04*") | E20: =COUNTIFS('Test Cases'!$C:$C,"*FR-K04*",'Test Cases'!$R:$R,"Passed") | F20: =IF(D20=0,"GAP",IF(E20=D20,"VERIFIED","PLANNED / INCOMPLETE"))
A21: FR-P01 | B21: FRS/SRS | C21: Payment methods/change | D21: =COUNTIF('Test Cases'!$C:$C,"*FR-P01*") | E21: =COUNTIFS('Test Cases'!$C:$C,"*FR-P01*",'Test Cases'!$R:$R,"Passed") | F21: =IF(D21=0,"GAP",IF(E21=D21,"VERIFIED","PLANNED / INCOMPLETE"))
A22: FR-P02 | B22: FRS/SRS | C22: Paid/table release | D22: =COUNTIF('Test Cases'!$C:$C,"*FR-P02*") | E22: =COUNTIFS('Test Cases'!$C:$C,"*FR-P02*",'Test Cases'!$R:$R,"Passed") | F22: =IF(D22=0,"GAP",IF(E22=D22,"VERIFIED","PLANNED / INCOMPLETE"))
A23: FR-P03 | B23: FRS/SRS | C23: Daily reports | D23: =COUNTIF('Test Cases'!$C:$C,"*FR-P03*") | E23: =COUNTIFS('Test Cases'!$C:$C,"*FR-P03*",'Test Cases'!$R:$R,"Passed") | F23: =IF(D23=0,"GAP",IF(E23=D23,"VERIFIED","PLANNED / INCOMPLETE"))
A24: FR-M01 | B24: FRS/SRS | C24: Menu maintenance | D24: =COUNTIF('Test Cases'!$C:$C,"*FR-M01*") | E24: =COUNTIFS('Test Cases'!$C:$C,"*FR-M01*",'Test Cases'!$R:$R,"Passed") | F24: =IF(D24=0,"GAP",IF(E24=D24,"VERIFIED","PLANNED / INCOMPLETE"))
A25: FR-M02 | B25: FRS/SRS | C25: Availability | D25: =COUNTIF('Test Cases'!$C:$C,"*FR-M02*") | E25: =COUNTIFS('Test Cases'!$C:$C,"*FR-M02*",'Test Cases'!$R:$R,"Passed") | F25: =IF(D25=0,"GAP",IF(E25=D25,"VERIFIED","PLANNED / INCOMPLETE"))
A26: FR-I01 | B26: FRS/SRS | C26: Inventory fields | D26: =COUNTIF('Test Cases'!$C:$C,"*FR-I01*") | E26: =COUNTIFS('Test Cases'!$C:$C,"*FR-I01*",'Test Cases'!$R:$R,"Passed") | F26: =IF(D26=0,"GAP",IF(E26=D26,"VERIFIED","PLANNED / INCOMPLETE"))
A27: FR-I02 | B27: FRS/SRS | C27: Low stock | D27: =COUNTIF('Test Cases'!$C:$C,"*FR-I02*") | E27: =COUNTIFS('Test Cases'!$C:$C,"*FR-I02*",'Test Cases'!$R:$R,"Passed") | F27: =IF(D27=0,"GAP",IF(E27=D27,"VERIFIED","PLANNED / INCOMPLETE"))
A28: FR-I03 | B28: FRS/SRS | C28: Suppliers/PO | D28: =COUNTIF('Test Cases'!$C:$C,"*FR-I03*") | E28: =COUNTIFS('Test Cases'!$C:$C,"*FR-I03*",'Test Cases'!$R:$R,"Passed") | F28: =IF(D28=0,"GAP",IF(E28=D28,"VERIFIED","PLANNED / INCOMPLETE"))
A29: FR-I04 | B29: FRS/SRS | C29: Adjustments | D29: =COUNTIF('Test Cases'!$C:$C,"*FR-I04*") | E29: =COUNTIFS('Test Cases'!$C:$C,"*FR-I04*",'Test Cases'!$R:$R,"Passed") | F29: =IF(D29=0,"GAP",IF(E29=D29,"VERIFIED","PLANNED / INCOMPLETE"))
A30: FR-I05 | B30: FRS/SRS | C30: Legacy Item Requests | D30: =COUNTIF('Test Cases'!$C:$C,"*FR-I05*") | E30: =COUNTIFS('Test Cases'!$C:$C,"*FR-I05*",'Test Cases'!$R:$R,"Passed") | F30: =IF(D30=0,"GAP",IF(E30=D30,"VERIFIED","PLANNED / INCOMPLETE"))
A31: FR-I06 | B31: FRS/SRS | C31: Branch request | D31: =COUNTIF('Test Cases'!$C:$C,"*FR-I06*") | E31: =COUNTIFS('Test Cases'!$C:$C,"*FR-I06*",'Test Cases'!$R:$R,"Passed") | F31: =IF(D31=0,"GAP",IF(E31=D31,"VERIFIED","PLANNED / INCOMPLETE"))
A32: FR-I07 | B32: FRS/SRS | C32: Decision/no stock | D32: =COUNTIF('Test Cases'!$C:$C,"*FR-I07*") | E32: =COUNTIFS('Test Cases'!$C:$C,"*FR-I07*",'Test Cases'!$R:$R,"Passed") | F32: =IF(D32=0,"GAP",IF(E32=D32,"VERIFIED","PLANNED / INCOMPLETE"))
A33: FR-I08 | B33: FRS/SRS | C33: Fulfillment role | D33: =COUNTIF('Test Cases'!$C:$C,"*FR-I08*") | E33: =COUNTIFS('Test Cases'!$C:$C,"*FR-I08*",'Test Cases'!$R:$R,"Passed") | F33: =IF(D33=0,"GAP",IF(E33=D33,"VERIFIED","PLANNED / INCOMPLETE"))
A34: FR-I09 | B34: FRS/SRS | C34: Atomic transfer | D34: =COUNTIF('Test Cases'!$C:$C,"*FR-I09*") | E34: =COUNTIFS('Test Cases'!$C:$C,"*FR-I09*",'Test Cases'!$R:$R,"Passed") | F34: =IF(D34=0,"GAP",IF(E34=D34,"VERIFIED","PLANNED / INCOMPLETE"))
A35: FR-I10 | B35: FRS/SRS | C35: Transfer audit | D35: =COUNTIF('Test Cases'!$C:$C,"*FR-I10*") | E35: =COUNTIFS('Test Cases'!$C:$C,"*FR-I10*",'Test Cases'!$R:$R,"Passed") | F35: =IF(D35=0,"GAP",IF(E35=D35,"VERIFIED","PLANNED / INCOMPLETE"))
A36: FR-I11 | B36: FRS/SRS | C36: Isolation | D36: =COUNTIF('Test Cases'!$C:$C,"*FR-I11*") | E36: =COUNTIFS('Test Cases'!$C:$C,"*FR-I11*",'Test Cases'!$R:$R,"Passed") | F36: =IF(D36=0,"GAP",IF(E36=D36,"VERIFIED","PLANNED / INCOMPLETE"))
A37: FR-S01 | B37: FRS/SRS | C37: Staff | D37: =COUNTIF('Test Cases'!$C:$C,"*FR-S01*") | E37: =COUNTIFS('Test Cases'!$C:$C,"*FR-S01*",'Test Cases'!$R:$R,"Passed") | F37: =IF(D37=0,"GAP",IF(E37=D37,"VERIFIED","PLANNED / INCOMPLETE"))
A38: FR-S02 | B38: FRS/SRS | C38: Restaurant/branches | D38: =COUNTIF('Test Cases'!$C:$C,"*FR-S02*") | E38: =COUNTIFS('Test Cases'!$C:$C,"*FR-S02*",'Test Cases'!$R:$R,"Passed") | F38: =IF(D38=0,"GAP",IF(E38=D38,"VERIFIED","PLANNED / INCOMPLETE"))
A39: FR-S03 | B39: FRS/SRS | C39: Tables | D39: =COUNTIF('Test Cases'!$C:$C,"*FR-S03*") | E39: =COUNTIFS('Test Cases'!$C:$C,"*FR-S03*",'Test Cases'!$R:$R,"Passed") | F39: =IF(D39=0,"GAP",IF(E39=D39,"VERIFIED","PLANNED / INCOMPLETE"))
A40: FR-D01 | B40: FRS/SRS | C40: Dashboard | D40: =COUNTIF('Test Cases'!$C:$C,"*FR-D01*") | E40: =COUNTIFS('Test Cases'!$C:$C,"*FR-D01*",'Test Cases'!$R:$R,"Passed") | F40: =IF(D40=0,"GAP",IF(E40=D40,"VERIFIED","PLANNED / INCOMPLETE"))
A41: FR-D02 | B41: FRS/SRS | C41: Management reports | D41: =COUNTIF('Test Cases'!$C:$C,"*FR-D02*") | E41: =COUNTIFS('Test Cases'!$C:$C,"*FR-D02*",'Test Cases'!$R:$R,"Passed") | F41: =IF(D41=0,"GAP",IF(E41=D41,"VERIFIED","PLANNED / INCOMPLETE"))
...

Sheet Test Data Plan
A1: Test Data Plan
A2: Safe synthetic data only. Credential values stay in an approved secret manager and are never copied here.
A4: Dataset ID | B4: Entity | C4: Synthetic record | D4: Restaurant | E4: Branch | F4: Purpose / boundary | G4: Creation method | H4: Reset method | I4: Sensitive-data rule
A5: TD-ORG-01 | B5: Restaurant | C5: Jima QA Restaurant A | D5: A | E5: — | F5: Primary tenant | G5: Controlled fixture/API | H5: Snapshot restore | I5: No real company contact data
A6: TD-ORG-02 | B6: Restaurant | C6: Jima QA Restaurant B | D6: B | E6: — | F6: Cross-tenant denial | G6: Controlled fixture/API | H6: Snapshot restore | I6: Clearly marked synthetic
A7: TD-BR-01 | B7: Branch | C7: Addis QA Branch A1 | D7: A | E7: A1 | F7: Primary branch | G7: Controlled fixture/API | H7: Snapshot restore | I7: Fake address/phone
A8: TD-BR-02 | B8: Branch | C8: Bole QA Branch A2 | D8: A | E8: A2 | F8: Cross-branch denial | G8: Controlled fixture/API | H8: Snapshot restore | I8: Fake address/phone
A9: TD-BR-03 | B9: Branch | C9: Bahir QA Branch B1 | D9: B | E9: B1 | F9: Cross-restaurant denial | G9: Controlled fixture/API | H9: Snapshot restore | I9: Fake address/phone
A10: TD-USR-01 | B10: Users | C10: One account for each of 9 identities | D10: A/B | E10: A1/A2/B1/none | F10: RBAC matrix incl. both storekeepers | G10: Admin provisioning | H10: Deactivate/delete fixture | I10: Use @example.test; password by secret alias only
A11: TD-MENU-01 | B11: Menu | C11: Categories and items: available/unavailable, ETB decimals | D11: A | E11: A1 | F11: POS, totals, boundary | G11: Manager UI/API | H11: Delete fixture | I11: No copied production menu required
A12: TD-TBL-01 | B12: Tables | C12: Available/occupied tables and duplicate-number candidate | D12: A | E12: A1/A2 | F12: Occupancy and isolation | G12: Manager UI/API | H12: Restore statuses | I12: No customer data
A13: TD-ORD-01 | B13: Orders | C13: One order at each lifecycle status plus concurrent candidate | D13: A | E13: A1 | F13: Lifecycle/payment/filters | G13: Supported workflows | H13: Complete/cancel or snapshot | I13: Fake notes and example phone
A14: TD-INV-01 | B14: Inventory | C14: Normal, warning, critical, zero, near-expiry, expired items | D14: A/B | E14: A1/A2/B1 | F14: Alerts/procurement/isolation | G14: Store UI/API | H14: Snapshot restore | I14: Known units/costs and recorded baselines
A15: TD-MS-01 | B15: Main Store | C15: Sufficient and insufficient multi-line items | D15: A/B | E15: none | F15: Atomic transfer/rollback | G15: Main Store receipt | H15: Snapshot restore | I15: Record central/branch balances before every case
A16: TD-EXP-01 | B16: Reports | C16: Known dates/methods/categories and zero-data range | D16: A | E16: A1 | F16: Filter/totals/export | G16: Supported workflows | H16: Snapshot restore | I16: No actual customer PII

Sheet Defect Log
A1: Defect ID | B1: Linked Test ID | C1: Severity | D1: Priority | E1: Status | F1: Title | G1: Environment / Build | H1: Steps to Reproduce | I1: Expected | J1: Actual | K1: Evidence Link | L1: Owner | M1: Target Fix | N1: Retest Result | O1: Notes

Sheet Daily Execution Summary
A1: Daily Execution Summary
A2: Enter date/tester/environment; execution counts are formula-driven from Test Cases.
A4: Date | B4: Tester | C4: Environment | D4: Planned | E4: Executed | F4: Passed | G4: Failed | H4: Blocked | I4: Pass % | J4: Defects opened | K4: Critical/High open | L4: Notes
D5: =COUNTIFS('Test Cases'!$V:$V,A5,'Test Cases'!$U:$U,B5,'Test Cases'!$W:$W,C5) | E5: =SUM(F5:H5) | F5: =COUNTIFS('Test Cases'!$V:$V,A5,'Test Cases'!$U:$U,B5,'Test Cases'!$W:$W,C5,'Test Cases'!$R:$R,"Passed") | G5: =COUNTIFS('Test Cases'!$V:$V,A5,'Test Cases'!$U:$U,B5,'Test Cases'!$W:$W,C5,'Test Cases'!$R:$R,"Failed") | H5: =COUNTIFS('Test Cases'!$V:$V,A5,'Test Cases'!$U:$U,B5,'Test Cases'!$W:$W,C5,'Test Cases'!$R:$R,"Blocked") | I5: =IFERROR(F5/E5,0) | J5: =COUNTIF('Defect Log'!$M:$M,A5) | K5: =COUNTIFS('Defect Log'!$C:$C,"Critical",'Defect Log'!$E:$E,"<>Closed")+COUNTIFS('Defect Log'!$C:$C,"High",'Defect Log'!$E:$E,"<>Closed")
D6: =COUNTIFS('Test Cases'!$V:$V,A6,'Test Cases'!$U:$U,B6,'Test Cases'!$W:$W,C6) | E6: =SUM(F6:H6) | F6: =COUNTIFS('Test Cases'!$V:$V,A6,'Test Cases'!$U:$U,B6,'Test Cases'!$W:$W,C6,'Test Cases'!$R:$R,"Passed") | G6: =COUNTIFS('Test Cases'!$V:$V,A6,'Test Cases'!$U:$U,B6,'Test Cases'!$W:$W,C6,'Test Cases'!$R:$R,"Failed") | H6: =COUNTIFS('Test Cases'!$V:$V,A6,'Test Cases'!$U:$U,B6,'Test Cases'!$W:$W,C6,'Test Cases'!$R:$R,"Blocked") | I6: =IFERROR(F6/E6,0) | J6: =COUNTIF('Defect Log'!$M:$M,A6) | K6: =COUNTIFS('Defect Log'!$C:$C,"Critical",'Defect Log'!$E:$E,"<>Closed")+COUNTIFS('Defect Log'!$C:$C,"High",'Defect Log'!$E:$E,"<>Closed")
D7: =COUNTIFS('Test Cases'!$V:$V,A7,'Test Cases'!$U:$U,B7,'Test Cases'!$W:$W,C7) | E7: =SUM(F7:H7) | F7: =COUNTIFS('Test Cases'!$V:$V,A7,'Test Cases'!$U:$U,B7,'Test Cases'!$W:$W,C7,'Test Cases'!$R:$R,"Passed") | G7: =COUNTIFS('Test Cases'!$V:$V,A7,'Test Cases'!$U:$U,B7,'Test Cases'!$W:$W,C7,'Test Cases'!$R:$R,"Failed") | H7: =COUNTIFS('Test Cases'!$V:$V,A7,'Test Cases'!$U:$U,B7,'Test Cases'!$W:$W,C7,'Test Cases'!$R:$R,"Blocked") | I7: =IFERROR(F7/E7,0) | J7: =COUNTIF('Defect Log'!$M:$M,A7) | K7: =COUNTIFS('Defect Log'!$C:$C,"Critical",'Defect Log'!$E:$E,"<>Closed")+COUNTIFS('Defect Log'!$C:$C,"High",'Defect Log'!$E:$E,"<>Closed")
D8: =COUNTIFS('Test Cases'!$V:$V,A8,'Test Cases'!$U:$U,B8,'Test Cases'!$W:$W,C8) | E8: =SUM(F8:H8) | F8: =COUNTIFS('Test Cases'!$V:$V,A8,'Test Cases'!$U:$U,B8,'Test Cases'!$W:$W,C8,'Test Cases'!$R:$R,"Passed") | G8: =COUNTIFS('Test Cases'!$V:$V,A8,'Test Cases'!$U:$U,B8,'Test Cases'!$W:$W,C8,'Test Cases'!$R:$R,"Failed") | H8: =COUNTIFS('Test Cases'!$V:$V,A8,'Test Cases'!$U:$U,B8,'Test Cases'!$W:$W,C8,'Test Cases'!$R:$R,"Blocked") | I8: =IFERROR(F8/E8,0) | J8: =COUNTIF('Defect Log'!$M:$M,A8) | K8: =COUNTIFS('Defect Log'!$C:$C,"Critical",'Defect Log'!$E:$E,"<>Closed")+COUNTIFS('Defect Log'!$C:$C,"High",'Defect Log'!$E:$E,"<>Closed")
D9: =COUNTIFS('Test Cases'!$V:$V,A9,'Test Cases'!$U:$U,B9,'Test Cases'!$W:$W,C9) | E9: =SUM(F9:H9) | F9: =COUNTIFS('Test Cases'!$V:$V,A9,'Test Cases'!$U:$U,B9,'Test Cases'!$W:$W,C9,'Test Cases'!$R:$R,"Passed") | G9: =COUNTIFS('Test Cases'!$V:$V,A9,'Test Cases'!$U:$U,B9,'Test Cases'!$W:$W,C9,'Test Cases'!$R:$R,"Failed") | H9: =COUNTIFS('Test Cases'!$V:$V,A9,'Test Cases'!$U:$U,B9,'Test Cases'!$W:$W,C9,'Test Cases'!$R:$R,"Blocked") | I9: =IFERROR(F9/E9,0) | J9: =COUNTIF('Defect Log'!$M:$M,A9) | K9: =COUNTIFS('Defect Log'!$C:$C,"Critical",'Defect Log'!$E:$E,"<>Closed")+COUNTIFS('Defect Log'!$C:$C,"High",'Defect Log'!$E:$E,"<>Closed")
D10: =COUNTIFS('Test Cases'!$V:$V,A10,'Test Cases'!$U:$U,B10,'Test Cases'!$W:$W,C10) | E10: =SUM(F10:H10) | F10: =COUNTIFS('Test Cases'!$V:$V,A10,'Test Cases'!$U:$U,B10,'Test Cases'!$W:$W,C10,'Test Cases'!$R:$R,"Passed") | G10: =COUNTIFS('Test Cases'!$V:$V,A10,'Test Cases'!$U:$U,B10,'Test Cases'!$W:$W,C10,'Test Cases'!$R:$R,"Failed") | H10: =COUNTIFS('Test Cases'!$V:$V,A10,'Test Cases'!$U:$U,B10,'Test Cases'!$W:$W,C10,'Test Cases'!$R:$R,"Blocked") | I10: =IFERROR(F10/E10,0) | J10: =COUNTIF('Defect Log'!$M:$M,A10) | K10: =COUNTIFS('Defect Log'!$C:$C,"Critical",'Defect Log'!$E:$E,"<>Closed")+COUNTIFS('Defect Log'!$C:$C,"High",'Defect Log'!$E:$E,"<>Closed")
D11: =COUNTIFS('Test Cases'!$V:$V,A11,'Test Cases'!$U:$U,B11,'Test Cases'!$W:$W,C11) | E11: =SUM(F11:H11) | F11: =COUNTIFS('Test Cases'!$V:$V,A11,'Test Cases'!$U:$U,B11,'Test Cases'!$W:$W,C11,'Test Cases'!$R:$R,"Passed") | G11: =COUNTIFS('Test Cases'!$V:$V,A11,'Test Cases'!$U:$U,B11,'Test Cases'!$W:$W,C11,'Test Cases'!$R:$R,"Failed") | H11: =COUNTIFS('Test Cases'!$V:$V,A11,'Test Cases'!$U:$U,B11,'Test Cases'!$W:$W,C11,'Test Cases'!$R:$R,"Blocked") | I11: =IFERROR(F11/E11,0) | J11: =COUNTIF('Defect Log'!$M:$M,A11) | K11: =COUNTIFS('Defect Log'!$C:$C,"Critical",'Defect Log'!$E:$E,"<>Closed")+COUNTIFS('Defect Log'!$C:$C,"High",'Defect Log'!$E:$E,"<>Closed")
D12: =COUNTIFS('Test Cases'!$V:$V,A12,'Test Cases'!$U:$U,B12,'Test Cases'!$W:$W,C12) | E12: =SUM(F12:H12) | F12: =COUNTIFS('Test Cases'!$V:$V,A12,'Test Cases'!$U:$U,B12,'Test Cases'!$W:$W,C12,'Test Cases'!$R:$R,"Passed") | G12: =COUNTIFS('Test Cases'!$V:$V,A12,'Test Cases'!$U:$U,B12,'Test Cases'!$W:$W,C12,'Test Cases'!$R:$R,"Failed") | H12: =COUNTIFS('Test Cases'!$V:$V,A12,'Test Cases'!$U:$U,B12,'Test Cases'!$W:$W,C12,'Test Cases'!$R:$R,"Blocked") | I12: =IFERROR(F12/E12,0) | J12: =COUNTIF('Defect Log'!$M:$M,A12) | K12: =COUNTIFS('Defect Log'!$C:$C,"Critical",'Defect Log'!$E:$E,"<>Closed")+COUNTIFS('Defect Log'!$C:$C,"High",'Defect Log'!$E:$E,"<>Closed")
D13: =COUNTIFS('Test Cases'!$V:$V,A13,'Test Cases'!$U:$U,B13,'Test Cases'!$W:$W,C13) | E13: =SUM(F13:H13) | F13: =COUNTIFS('Test Cases'!$V:$V,A13,'Test Cases'!$U:$U,B13,'Test Cases'!$W:$W,C13,'Test Cases'!$R:$R,"Passed") | G13: =COUNTIFS('Test Cases'!$V:$V,A13,'Test Cases'!$U:$U,B13,'Test Cases'!$W:$W,C13,'Test Cases'!$R:$R,"Failed") | H13: =COUNTIFS('Test Cases'!$V:$V,A13,'Test Cases'!$U:$U,B13,'Test Cases'!$W:$W,C13,'Test Cases'!$R:$R,"Blocked") | I13: =IFERROR(F13/E13,0) | J13: =COUNTIF('Defect Log'!$M:$M,A13) | K13: =COUNTIFS('Defect Log'!$C:$C,"Critical",'Defect Log'!$E:$E,"<>Closed")+COUNTIFS('Defect Log'!$C:$C,"High",'Defect Log'!$E:$E,"<>Closed")
D14: =COUNTIFS('Test Cases'!$V:$V,A14,'Test Cases'!$U:$U,B14,'Test Cases'!$W:$W,C14) | E14: =SUM(F14:H14) | F14: =COUNTIFS('Test Cases'!$V:$V,A14,'Test Cases'!$U:$U,B14,'Test Cases'!$W:$W,C14,'Test Cases'!$R:$R,"Passed") | G14: =COUNTIFS('Test Cases'!$V:$V,A14,'Test Cases'!$U:$U,B14,'Test Cases'!$W:$W,C14,'Test Cases'!$R:$R,"Failed") | H14: =COUNTIFS('Test Cases'!$V:$V,A14,'Test Cases'!$U:$U,B14,'Test Cases'!$W:$W,C14,'Test Cases'!$R:$R,"Blocked") | I14: =IFERROR(F14/E14,0) | J14: =COUNTIF('Defect Log'!$M:$M,A14) | K14: =COUNTIFS('Defect Log'!$C:$C,"Critical",'Defect Log'!$E:$E,"<>Closed")+COUNTIFS('Defect Log'!$C:$C,"High",'Defect Log'!$E:$E,"<>Closed")
D15: =COUNTIFS('Test Cases'!$V:$V,A15,'Test Cases'!$U:$U,B15,'Test Cases'!$W:$W,C15) | E15: =SUM(F15:H15) | F15: =COUNTIFS('Test Cases'!$V:$V,A15,'Test Cases'!$U:$U,B15,'Test Cases'!$W:$W,C15,'Test Cases'!$R:$R,"Passed") | G15: =COUNTIFS('Test Cases'!$V:$V,A15,'Test Cases'!$U:$U,B15,'Test Cases'!$W:$W,C15,'Test Cases'!$R:$R,"Failed") | H15: =COUNTIFS('Test Cases'!$V:$V,A15,'Test Cases'!$U:$U,B15,'Test Cases'!$W:$W,C15,'Test Cases'!$R:$R,"Blocked") | I15: =IFERROR(F15/E15,0) | J15: =COUNTIF('Defect Log'!$M:$M,A15) | K15: =COUNTIFS('Defect Log'!$C:$C,"Critical",'Defect Log'!$E:$E,"<>Closed")+COUNTIFS('Defect Log'!$C:$C,"High",'Defect Log'!$E:$E,"<>Closed")
D16: =COUNTIFS('Test Cases'!$V:$V,A16,'Test Cases'!$U:$U,B16,'Test Cases'!$W:$W,C16) | E16: =SUM(F16:H16) | F16: =COUNTIFS('Test Cases'!$V:$V,A16,'Test Cases'!$U:$U,B16,'Test Cases'!$W:$W,C16,'Test Cases'!$R:$R,"Passed") | G16: =COUNTIFS('Test Cases'!$V:$V,A16,'Test Cases'!$U:$U,B16,'Test Cases'!$W:$W,C16,'Test Cases'!$R:$R,"Failed") | H16: =COUNTIFS('Test Cases'!$V:$V,A16,'Test Cases'!$U:$U,B16,'Test Cases'!$W:$W,C16,'Test Cases'!$R:$R,"Blocked") | I16: =IFERROR(F16/E16,0) | J16: =COUNTIF('Defect Log'!$M:$M,A16) | K16: =COUNTIFS('Defect Log'!$C:$C,"Critical",'Defect Log'!$E:$E,"<>Closed")+COUNTIFS('Defect Log'!$C:$C,"High",'Defect Log'!$E:$E,"<>Closed")
... D104: =COUNTIFS('Test Cases'!$V:$V,A104,'Test Cases'!$U:$U,B104,'Test Cases'!$W:$W,C104) | E104: =SUM(F104:H104) | F104: =COUNTIFS('Test Cases'!$V:$V,A104,'Test Cases'!$U:$U,B104,'Test Cases'!$W:$W,C104,'Test Cases'!$R:$R,"Passed") | G104: =COUNTIFS('Test Cases'!$V:$V,A104,'Test Cases'!$U:$U,B104,'Test Cases'!$W:$W,C104,'Test Cases'!$R:$R,"Failed") | H104: =COUNTIFS('Test Cases'!$V:$V,A104,'Test Cases'!$U:$U,B104,'Test Cases'!$W:$W,C104,'Test Cases'!$R:$R,"Blocked") | I104: =IFERROR(F104/E104,0) | J104: =COUNTIF('Defect Log'!$M:$M,A104) | K104: =COUNTIFS('Defect Log'!$C:$C,"Critical",'Defect Log'!$E:$E,"<>Closed")+COUNTIFS('Defect Log'!$C:$C,"High",'Defect Log'!$E:$E,"<>Closed")

Sheet UAT Sign-off
A1: UAT Sign-off
A2: Signatures are valid only after mandatory QA gates pass. Blank or conditional entries do not approve deployment.
A4: Area | B4: Business representative | C4: Role | D4: Acceptance scenario | E4: Decision | F4: Signature / controlled reference | G4: Date | H4: Comments / conditions
A5: Front of house | C5: Waiter/Coordinator/Cashier | D5: Order → kitchen → serve → payment/table release | E5: Not Reviewed
A6: Kitchen | C6: Chef lead | D6: Assigned queue and ready flow | E6: Not Reviewed
A7: Branch store | C7: Branch Storekeeper/Manager | D7: Inventory, legacy Item Request, Branch Stock Request/decision | E7: Not Reviewed
A8: Main Store | C8: Main Store Storekeeper | D8: Receipt and approved atomic fulfillment | E8: Not Reviewed
A9: Management | C9: Owner/Manager | D9: Dashboard, staff, branches, reports and exports | E9: Not Reviewed
A10: Final business approval | C10: Product Owner | D10: All accepted UAT scenarios and residual risks | E10: Not Reviewed

Sheet Release Gate Checklist
A1: Release Gate Checklist
